Workbook
Name Actual_Expenses: #REF!
Name Actual_Income: #REF!
Name Centralize: 'BRD & EPIC'!#REF!
Name Centralize: 'BRD & EPIC (2)'!#REF!
Name Centralize: #REF!
Name ColumnTitle1: #REF!
Name ColumnTitleRegion1..B4.1: #REF!
Name ColumnTitleRegion2..C9.1: #REF!
Name Company_Name: #REF!
Name Create_and_edit_plan: 'BRD & EPIC'!#REF!
Name Create_and_edit_plan: 'BRD & EPIC (2)'!#REF!
Name Create_and_edit_plan: #REF!
Name List_Categories: #REF!
Name Map_view_and_route: 'BRD & EPIC'!#REF!
Name Map_view_and_route: 'BRD & EPIC (2)'!#REF!
Name Map_view_and_route: #REF!
Name Projected_Expenses: #REF!
Name Projected_Income: #REF!
Name Rule_based_upsell_capability: 'BRD & EPIC'!#REF!
Name Rule_based_upsell_capability: 'BRD & EPIC (2)'!#REF!
Name Rule_based_upsell_capability: #REF!
Name SHDR_Options: '1_Standard Part'!#REF!
Name SHDR_Options: #REF!
Name SHDR_Options: #REF!
Name SHDR_Options: #REF!
Name SHDR_Options: #REF!
Name US_Options: '1_Standard Part'!#REF!
Name US_Options: #REF!
Name US_Options: #REF!
Name US_Options: #REF!
Name US_Options: #REF!
Name Vendor_Options: '1_Standard Part'!#REF!
Name Vendor_Options: #REF!
Name Vendor_Options: #REF!
Name Vendor_Options: #REF!
Name Vendor_Options: #REF!
Name WeekStart: 'BRD & EPIC'!#REF!
Name WeekStart: 'BRD & EPIC (2)'!#REF!

Sheet DE_Cost
A1: Sprint Buffer | B1: 1.2 | C1: 1.4
A2: PM Ratio of Developer | B2: 0.18 | C2: 1.18
A3: DM Ratio of Developer | B3: 0.15 | C3: 0.1
A4: QA Ratio of Developer | B4: 1.5 | C4: 0.1
A5: Android Ratio of Developer | B5: 1.2 | C5: 1.2
A6: Front Ratio of Developer | B6: 1 | C6: 1.2
A7: Backend Ratio of Developer | B7: 1 | C7: 1
A8: DM Tech Ratio of Developer | B8: 0.15 | C8: 0.1
A9: UI Design Ratio of Developer | B9: 0.12 | C9: 1.2
A10: OTE Ratio | B10: 0.5 | C10: 0.5
A11: Type | B11: Hour | C11: RMB | D11: USD | F11: Role(ND) | G11: Days | H11: Hours | I11: Cost/H | J11: RMB | K11: Rate | L11: USD
A12: SE | B12: 320 | C12: =B12*314 -> 100480 | D12: =C12/6.84 -> 14690.058 | F12: Back-End | G12: 272 | H12: =G12*8 -> 2176 | I12: 314 | J12: =H12*I12 -> 683264 | K12: 6.84 | L12: =J12/K12 -> 99892.398
A13: Coupon | B13: =400+400 -> 800 | C13: =B13*314 -> 251200 | D13: =C13/6.84 -> 36725.146 | F13: Back-End | G13: 272 | H13: =G13*8 -> 2176 | I13: 314 | J13: =H13*I13 -> 683264 | K13: 6.84 | L13: =J13/K13 -> 99892.398
A14: Shopping Cart | B14: =480+480 -> 960 | C14: =B14*314 -> 301440 | D14: =C14/6.84 -> 44070.175 | F14: Front-End | G14: 272 | H14: =G14*8 -> 2176 | I14: 314 | J14: =H14*I14 -> 683264 | K14: 6.84 | L14: =J14/K14 -> 99892.398
A15: Ticketing | B15: =400+320 -> 720 | C15: =B15*314 -> 226080 | D15: =C15/6.84 -> 33052.632 | F15: Front-End | G15: 272 | H15: =G15*8 -> 2176 | I15: 314 | J15: =H15*I15 -> 683264 | K15: 6.84 | L15: =J15/K15 -> 99892.398
A16: Other | B16: =440 + 16 + 160 + 264 + 480 + 16 -> 1376 | C16: =B16*314 -> 432064 | D16: =C16/6.84 -> 63167.251 | F16: QA | G16: 272 | H16: =G16*8 -> 2176 | I16: 266 | J16: =H16*I16 -> 578816 | K16: 6.84 | L16: =J16/K16 -> 84622.222
A17: Total | B17: =SUM(B10:B16) -> 4176.5 | C17: =B17*314 -> 1311421 | D17: =C17/6.84 -> 191728.22 | F17: QA | G17: 272 | H17: =G17*8 -> 2176 | I17: 266 | J17: =H17*I17 -> 578816 | K17: 6.84 | L17: =J17/K17 -> 84622.222
F18: QA | G18: 272 | H18: =G18*8 -> 2176 | I18: 266 | J18: =H18*I18 -> 578816 | K18: 6.84 | L18: =J18/K18 -> 84622.222
F19: Total | G19: =SUM(G12:G18) -> 1904 | H19: =G19*8 -> 15232 | J19: =SUM(J12:J18) -> 4469504 | K19: 6.84 | L19: =SUM(L12:L18) -> 653436.26
I21: Cost/H | K21: Rate | L21: USD | M21: USD/Month
F22: Team Cost | I22: =SUM(I12:I18) -> 2054 | K22: 6.84 | L22: =I22/K22 -> 300.2924 | M22: =I22/K22*8*21.75 -> 52250.877
F24: Timeline ND Cost | L24: =F80 -> 450720
F25: Planned ND Capex Cost | L25: =GETPIVOTDATA("Sum of Amount USD",$A$89,"CAPEX/ OTE","CAPEX","Asset","Tmall Gift Card","Team","Digital Engineering")-L26 -> 724294.81
F26: Planned CM Capex Cost | L26: =GETPIVOTDATA("Sum of Amount USD",$A$89,"CAPEX/ OTE","CAPEX","Vendor/SHDR","SHDR","Asset","Tmall Gift Card","Team","Digital Engineering","Role list","Delivery Manager") -> 84911.118
F27: Planned CM OTE Cost | L27: =GETPIVOTDATA("Sum of Amount USD",$A$89,"CAPEX/ OTE","OTE","Asset","Tmall Gift Card","Team","Digital Engineering") -> 68565.727
F28: Planned OTHER ASSET Capex Cost | L28: =GETPIVOTDATA("Sum of Amount USD",$A$89,"CAPEX/ OTE","CAPEX","Asset","Ticketing Commerce","Team","Digital Engineering") +GETPIVOTDATA("Sum of Amount USD",$A$89,"CAPEX/ OTE","CAPEX","Asset","Shopping Cart","Team","Digital Engineering") -> 71402.005
F29: Planned OTHER ASSET OTE Cost | L29: =GETPIVOTDATA("Sum of Amount USD",$A$89,"CAPEX/ OTE","OTE","Asset","Ticketing Commerce","Team","Digital Engineering") +GETPIVOTDATA("Sum of Amount USD",$A$89,"CAPEX/ OTE","OTE","Asset","Shopping Cart","Team","Digital Engineering") -> 21510.816
F30: Min Over Cost | L30: =L25+L26+L27-L24-L28-L29 -> 334138.84 | M30: =L30/M22 -> 6.3948943
F31: Max Over Cost | L31: =L25+L26+L27-L24 -> 427051.66 | M31: =L31/M22 -> 8.1731002
F32: Min Over Cost(CAPEX Only) | L32: =L25+L26-L24-L28-L29 -> 265573.11 | M32: =L32/M22 -> 5.0826536
A34: BRD Overview | B34: BRD Priority | C34: BRD Detailed Requirement | D34: EPIC Title | E34: EPIC Story | F34: Task / Description | G34: CAPEX/ OTE | H34: Release | I34: Vendor/SHDR | J34: Cost Type | K34: Asset | L34: Team | M34: Role list | N34: Contractor (Y/N) | O34: Contractor Level | P34: New Hiring (Y/N) | Q34: Refresh/Replacement (Y/N) | R34: Labor Hours/ Quantities | S34: Rate / Unit Price RMB | T34: Amount RMB | U34: Amount USD | V34: Comments
A35: 1. Card Manufacture 礼品卡制造 | B35: 5 | C35: 1.1 Card Foundation Data Mgmt. and Purchase | D35: 1.1.2 Card Foundation Data|sales information | E35: 1.1.2 As Tmall Gift Card operation, I need define card data format, as manage card foundation data with sales information 作为天猫礼品卡运营，需要定义礼品卡数据格式，以便实现按卡号管理的礼品卡数据基础 | F35: Requirment Analysis | G35: CAPEX | H35: Release 1 | I35: SHDR | J35: Labor | K35: Tmall Gift Card | L35: Digital Product | M35: Product Manager | N35: {=Contractor(I35,J35)} -> #NAME? | P35: N | R35: 44 | S35: 0 | T35: =S35*R35 -> 0 | U35: 0
A36: 1. Card Manufacture 礼品卡制造 | B36: 5 | C36: 1.1 Card Foundation Data Mgmt. and Purchase | D36: 1.1.2 Card Foundation Data|sales information | E36: 1.1.2 As Tmall Gift Card operation, I need define card data format, as manage card foundation data with sales information 作为天猫礼品卡运营，需要定义礼品卡数据格式，以便实现按卡号管理的礼品卡数据基础 | F36: Project Management | G36: OTE | H36: Release 1 | I36: SHDR | J36: Labor | K36: Tmall Gift Card | L36: Digital Engineering | M36: Product Manager | N36: {=Contractor(I36,J36)} -> #NAME? | P36: N | R36: 36 | S36: 483.99337 | T36: =S36*R36 -> 17423.761 | U36: 2547.3335
A37: 1. Card Manufacture 礼品卡制造 | B37: 5 | C37: 1.1 Card Foundation Data Mgmt. and Purchase | D37: 1.1.2 Card Foundation Data|sales information | E37: 1.1.2 As Tmall Gift Card operation, I need define card data format, as manage card foundation data with sales information 作为天猫礼品卡运营，需要定义礼品卡数据格式，以便实现按卡号管理的礼品卡数据基础 | F37: Front-End Development | G37: CAPEX | H37: Release 1 | I37: Vendor | J37: Labor | K37: Tmall Gift Card | L37: Digital Engineering | M37: Front-end Developer | N37: {=Contractor(I37,J37)} -> #NAME? | O37: Level 4 (5-8Years) | P37: Y | R37: 240 | S37: 383.99994 | T37: =S37*R37 -> 92159.986 | U37: 13473.682
A38: 1. Card Manufacture 礼品卡制造 | B38: 5 | C38: 1.1 Card Foundation Data Mgmt. and Purchase | D38: 1.1.2 Card Foundation Data|sales information | E38: 1.1.2 As Tmall Gift Card operation, I need define card data format, as manage card foundation data with sales information 作为天猫礼品卡运营，需要定义礼品卡数据格式，以便实现按卡号管理的礼品卡数据基础 | F38: Back-End Development | G38: CAPEX | H38: Release 1 | I38: Vendor | J38: Labor | K38: Tmall Gift Card | L38: Digital Engineering | M38: Back-end Developer | N38: {=Contractor(I38,J38)} -> #NAME? | O38: Level 4 (5-8Years) | P38: Y | R38: 240 | S38: 0 | T38: =S38*R38 -> 0 | U38: 0
A39: 1. Card Manufacture 礼品卡制造 | B39: 5 | C39: 1.1 Card Foundation Data Mgmt. and Purchase | D39: 1.1.2 Card Foundation Data|sales information | E39: 1.1.2 As Tmall Gift Card operation, I need define card data format, as manage card foundation data with sales information 作为天猫礼品卡运营，需要定义礼品卡数据格式，以便实现按卡号管理的礼品卡数据基础 | F39: Function Testing | G39: CAPEX | H39: Release 1 | I39: Vendor | J39: Labor | K39: Tmall Gift Card | L39: Digital Engineering | M39: Quality Assurance | N39: {=Contractor(I39,J39)} -> #NAME? | O39: Level 4 (5-8Years) | P39: Y | R39: 240 | S39: 0 | T39: =S39*R39 -> 0 | U39: 0
A42: Project | B42: Resource Name | C42: Total person / Days | D42: Total person / hours | E42: Rate (usd) | F42: Cost (usd) | G42: w1 | H42: w2 | I42: w3 | J42: w4 | K42: w5 | L42: w6 | M42: w7 | N42: w8 | O42: w9 | P42: w10 | Q42: w11 | R42: w12 | S42: w13 | T42: w14 | U42: w15 | V42: w16 | W42: w17 | X42: w18 | Y42: w19 | Z42: w20 | AA42: w21 | AB42: w22 | AC42: w23 | AD42: w24 | AE42: w25 | AF42: w26 | AG42: w27 | AH42: w28 | AI42: w21 | AJ42: w22 | AK42: w23 | AL42: w24 | AM42: w25 | AN42: w26 | AO42: w27
G43: 45689 | H43: =G43+7 -> 45696 | I43: =H43+7 -> 45703 | J43: =I43+7 -> 45710 | K43: =J43+7 -> 45717 | L43: =K43+7 -> 45724 | M43: =L43+7 -> 45731 | N43: =M43+7 -> 45738 | O43: =N43+7 -> 45745 | ... AZ43: =AY43+7 -> 46004
G44: Sprint 1 | I44: Sprint 2 | K44: Sprint 3 | M44: Sprint 4 | O44: Sprint 5 | Q44: Sprint 6 | S44: Sprint 7 | U44: Sprint 8 | W44: Sprint 9 | Y44: Sprint 10 | AA44: Sprint 11 | AC44: Sprint 12 | AE44: Sprint 13 | AG44: Sprint 14 | AI44: Sprint 15 | AK44: Sprint 16 | AM44: Sprint 17 | AO44: Sprint 18 | AQ44: Sprint 19 | AS44: Sprint 20 | AU44: Sprint 21 | AW44: Sprint 22 | AY44: Sprint 23
G45: Development | AI45: SIT | AM45: UAT | AO45: FIT
...

Sheet Cost Breakdown
A1: Project Category | B1: 点击返回说明页 Back to Instructions
A2: Commercial
A4: BRD Overview | B4: BRD Priority | C4: BRD Detailed Requirement | D4: EPIC Title | E4: EPIC Story | F4: Task / Description | G4: CAPEX/ OTE | H4: Release | I4: Vendor/SHDR | J4: Cost Type | K4: Asset | L4: Team | M4: Role list | N4: Contractor (Y/N) | O4: Contractor Level | P4: New Hiring (Y/N) | Q4: Refresh/Replacement (Y/N) | R4: Labor Hours/ Quantities | S4: Rate / Unit Price RMB | T4: Amount RMB | U4: Amount USD | V4: Comments
A5: 1. Card Manufacture 礼品卡制造 | B5: 5 | C5: 1.1 Card Foundation Data Mgmt. and Purchase | D5: 1.1.2 Card Foundation Data|sales information | E5: 1.1.2 As Tmall Gift Card operation, I need define card data format, as manage card foundation data with sales information 作为天猫礼品卡运营，需要定义礼品卡数据格式，以便实现按卡号管理的礼品卡数据基础 | F5: Requirment Analysis | G5: CAPEX | H5: Release 1 | I5: SHDR | J5: Labor | K5: Unified Gift Card - Card Foundation Data Mgt | L5: Digital Product | M5: Product Manager | N5: {=Contractor(I5,J5)} -> #NAME? | P5: N | R5: 44 | S5: 0 | T5: =S5*R5 -> 0 | U5: 0

Sheet BRD & EPIC (2)
A1: EPIC - Project Name | F1: 点击返回说明页 Back to Instructions | Y1: 0
A2: LOB VP Signature | C2: Tony Castillo/Steve Sulaski | D2: Date
A3: PM Diretctor Level Sigature | C3: Jimmy Lee | D3: Date
A4: DM Diretctor Level Sigature | C4: Peter Zhang | D4: Date
A6: BRD Priority | B6: 0. BRD Overview | C6: 0.0 BRD Detailed Requirement | D6: 0.0.0 EPIC Title | E6: 0.0.0.0 EPIC Story | F6: Description | G6: Dependencies | H6: EPIC Story(CN) | I6: Description(CN) | J6: Comment | K6: Follow-up Group | L6: Follow-up | M6: Follow-up with vendor | N6: Task Title | O6: Task Description | P6: system type | Q6: system tpye ultimately | R6: system type2 | S6: follw up PM | T6: follow up | U6: Develop Labor(man/day) | V6: Real Develop Labor(Man/Hour) | W6: Real Develop Labor(Man/Day) | X6: 表设计 | Y6: 表个数 | Z6: task count | AA6: Review Pass | AB6: Lucky Comment | AC6: check content change | AD6: task sum count
A7: 0 | B7: 0. Project Foundation | C7: 0.1 SE|Hosting | D7: 0.1.1 SE|System deployment in Cloud | E7: 0.1.1.1 Services/systems set up in cloud, Create new cloud accounts, New vendor system support in Cloud | G7: SE | H7: 0.1.1.1 在云中设置的服务/系统，创建新的云账户，在云中支持新的供应商系统 | Q7: =BRD_EPIC2[[#This Row],[system type]]&BRD_EPIC2[[#This Row],[system type2]] | V7: =$U7*DE_Cost!$B$1*8 -> 0 | W7: =$U7*DE_Cost!$B$1 -> 0 | AA7: Y
D8: 0.1.2 SE|System deployment on-premise | E8: 0.1.2.1 Services/systems deployment/configurition/automation for new servers in on-premise datacenter | G8: SE | H8: 0.1.2.1 本地数据中心新服务器部署/配置/自动化服务/系统 | Q8: =BRD_EPIC2[[#This Row],[system type]]&BRD_EPIC2[[#This Row],[system type2]] | V8: =$U8*DE_Cost!$B$1*8 -> 0 | W8: =$U8*DE_Cost!$B$1 -> 0 | AA8: Y
D9: 0.1.3 SE|Database deployment in Cloud | E9: 0.1.3.1 Database set up in cloud, dashboard requirements, database schema changes, data migration | G9: SE | H9: 0.1.3.1 云端数据库设置，仪表板需求，数据库架构变更，数据迁移 | Q9: =BRD_EPIC2[[#This Row],[system type]]&BRD_EPIC2[[#This Row],[system type2]] | V9: =$U9*DE_Cost!$B$1*8 -> 0 | W9: =$U9*DE_Cost!$B$1 -> 0 | AA9: Y
D10: 0.1.4 SE|Cloud Hosting | E10: 0.1.4.1 Hosting fee in AliCloud, AWS | G10: SE | H10: 0.1.4.1 阿里云、AWS 托管费用 | Q10: =BRD_EPIC2[[#This Row],[system type]]&BRD_EPIC2[[#This Row],[system type2]] | V10: =$U10*DE_Cost!$B$1*8 -> 0 | W10: =$U10*DE_Cost!$B$1 -> 0 | AA10: Y
D11: 0.1.5 SE|Hardware purchase | E11: 0.1.5.1 New servers/storage/devices in on-premise datacenter | G11: SE | H11: 0.1.5.1 本地数据中心中的新服务器/存储设备 | Q11: =BRD_EPIC2[[#This Row],[system type]]&BRD_EPIC2[[#This Row],[system type2]] | V11: =$U11*DE_Cost!$B$1*8 -> 0 | W11: =$U11*DE_Cost!$B$1 -> 0 | AA11: Y
D12: 0.1.6 SE|Vendor Service | E12: 0.1.6.1 3rd party vendor services | G12: SE | H12: 0.1.6.1 第三方供应商服务 | Q12: =BRD_EPIC2[[#This Row],[system type]]&BRD_EPIC2[[#This Row],[system type2]] | V12: =$U12*DE_Cost!$B$1*8 -> 0 | W12: =$U12*DE_Cost!$B$1 -> 0 | AA12: Y
D13: 0.1.7 SE|License|Software | E13: 0.1.7.1 License cost for hardware/software | G13: SE | H13: 0.1.7.1 硬件/软件的许可费用 | Q13: =BRD_EPIC2[[#This Row],[system type]]&BRD_EPIC2[[#This Row],[system type2]] | V13: =$U13*DE_Cost!$B$1*8 -> 0 | W13: =$U13*DE_Cost!$B$1 -> 0 | AA13: Y
C14: 0.2 QO|GQE | D14: 0.2.1 GQE |Manual Testing | E14: 0.2.1.1 Design test cases, execute test cases, analyze defects, write test reports for Manual Testing. | G14: QO | H14: 0.2.1.1 设计测试用例，执行测试用例，分析缺陷，编写手动测试报告。 | K14: QO | Q14: =BRD_EPIC2[[#This Row],[system type]]&BRD_EPIC2[[#This Row],[system type2]] | V14: =$U14*DE_Cost!$B$1*8 -> 0 | W14: =$U14*DE_Cost!$B$1 -> 0 | AA14: Y
D15: 0.2.2 GQE |Automation Testing | E15: 0.2.2.1 Design test cases, encode test cases, execute automation scripts, analyze defects, write test reports for Automation Testing. | G15: QO | H15: 0.2.2.1 设计测试用例，编码测试用例，执行自动化脚本，分析缺陷，编写自动化测试报告。 | K15: QO | Q15: =BRD_EPIC2[[#This Row],[system type]]&BRD_EPIC2[[#This Row],[system type2]] | V15: =$U15*DE_Cost!$B$1*8 -> 0 | W15: =$U15*DE_Cost!$B$1 -> 0 | AA15: Y
D16: 0.2.3 GQE |Performance Testing | E16: 0.2.3.1 Design test cases, encode test cases, execute performance test cases, analyze defects, write test reports for Performance Testing. | G16: QO | H16: 0.2.3.1 设计测试用例，编码测试用例，执行性能测试用例，分析缺陷，编写性能测试报告。 | K16: QO | Q16: =BRD_EPIC2[[#This Row],[system type]]&BRD_EPIC2[[#This Row],[system type2]] | V16: =$U16*DE_Cost!$B$1*8 -> 0 | W16: =$U16*DE_Cost!$B$1 -> 0 | AA16: Y
D17: 0.2.4 GQE |Command Center Support | E17: 0.2.4.1 Support command centers during launch and hypercare period. | G17: QO | H17: 0.2.4.1 在发布和超保支持期间支持指挥中心。 | K17: QO | Q17: =BRD_EPIC2[[#This Row],[system type]]&BRD_EPIC2[[#This Row],[system type2]] | V17: =$U17*DE_Cost!$B$1*8 -> 0 | W17: =$U17*DE_Cost!$B$1 -> 0 | AA17: Y
C18: 0.3 QO|Release Management | D18: 0.3.1 RM |Change and Release Support | E18: 0.3.1.1 Plan, design, schedule, validate, deploy and control system changes and releases to support system launches. | G18: QO | H18: 0.3.1.1 计划、设计、安排、验证、部署和控制系统变更与发布，以支持系统上线。 | K18: QO | Q18: =BRD_EPIC2[[#This Row],[system type]]&BRD_EPIC2[[#This Row],[system type2]] | V18: =$U18*DE_Cost!$B$1*8 -> 0 | W18: =$U18*DE_Cost!$B$1 -> 0 | AA18: Y
D19: 0.3.2 RM |Command Center Support | E19: 0.3.2.1 Support command centers during hypercare period. | G19: QO | H19: 0.3.2.1 在超保期间支持指挥中心。 | K19: QO | Q19: =BRD_EPIC2[[#This Row],[system type]]&BRD_EPIC2[[#This Row],[system type2]] | V19: =$U19*DE_Cost!$B$1*8 -> 0 | W19: =$U19*DE_Cost!$B$1 -> 0 | AA19: Y
C20: 0.4 QO|Incident Management | D20: 0.4.1 L2 |Configuration Management | E20: 0.4.1.1 Perform configuration changes on TYK, ACP, UAP, VDM. | G20: QO | H20: 0.4.1.1 在 TYK、ACP、UAP、VDM 上执行配置更改。 | J20: 确认Onsite时间， L2需要规划成员支持 7天，7:~23 | K20: QO | Q20: =BRD_EPIC2[[#This Row],[system type]]&BRD_EPIC2[[#This Row],[system type2]] | V20: =$U20*DE_Cost!$B$1*8 -> 0 | W20: =$U20*DE_Cost!$B$1 -> 0 | AA20: Y
D21: 0.4.2 L2 |Command Center Coordination and Support | E21: 0.4.2.1 Plan and implement command centers to support launches. | G21: QO | H21: 0.4.2.1 规划并实施支持发射的指挥中心。 | J21: 确认try run时间，住酒店40人/1000 | K21: QO | Q21: =BRD_EPIC2[[#This Row],[system type]]&BRD_EPIC2[[#This Row],[system type2]] | V21: =$U21*DE_Cost!$B$1*8 -> 0 | W21: =$U21*DE_Cost!$B$1 -> 0 | AA21: Y
C22: 0.5 QO|Problem Management | D22: 0.5.1 Problem Management |Proactive Problem Management | E22: 0.5.1.1 Follow all opened defects that will move to production with the launch and drive the resolution of defects before they turn into incidents. | G22: QO | H22: 0.5.1.1 跟踪所有将随发布移至生产环境的缺陷，并在其演变为事件前推动解决这些缺陷。 | J22: 需要确认我们自己是否介入测试 | K22: QO | Q22: =BRD_EPIC2[[#This Row],[system type]]&BRD_EPIC2[[#This Row],[system type2]] | V22: =$U22*DE_Cost!$B$1*8 -> 0 | W22: =$U22*DE_Cost!$B$1 -> 0 | AA22: Y
C23: 0.6 InfoSec|Information Security | D23: 0.6.1 InfoSec|Security Terms Review in the Contract | E23: 0.6.1.1 Whenever the 3rd party provider would like to change the default information security terms and schedules, the project team needs to contact InfoSec for change review. | G23: Security | H23: 0.6.1.1 当第三方提供商希望更改默认信息安全条款和时间表时，项目团队需要联系信息安全部门进行变更审核。 | Q23: =BRD_EPIC2[[#This Row],[system type]]&BRD_EPIC2[[#This Row],[system type2]] | V23: =$U23*DE_Cost!$B$1*8 -> 0 | W23: =$U23*DE_Cost!$B$1 -> 0 | AA23: Y
D24: 0.6.2 InfoSec|Information Security Assessment (ISA) | E24: 0.6.2.1 All the new applications and significant change to the existing applications need to complete the information security assessment. | G24: Security | H24: 0.6.2.1 所有新应用及对现有应用的重大变更均需完成信息安全评估。 | Q24: =BRD_EPIC2[[#This Row],[system type]]&BRD_EPIC2[[#This Row],[system type2]] | V24: =$U24*DE_Cost!$B$1*8 -> 0 | W24: =$U24*DE_Cost!$B$1 -> 0 | AA24: Y
D25: 0.6.3 InfoSec|RFP Security Questionnaire and/or Third Party Assessment (TPA) | E25: 0.6.3.1 If a 3rd party provider is involved, RFP security questionnaire is mandatory to be filled, and if necessary the Third Party Assessment should be conducted. | G25: Security | H25: 0.6.3.1 如果涉及第三方供应商，则必须填写 RFP 安全问卷，并在必要时进行第三方评估。 | Q25: =BRD_EPIC2[[#This Row],[system type]]&BRD_EPIC2[[#This Row],[system type2]] | V25: =$U25*DE_Cost!$B$1*8 -> 0 | W25: =$U25*DE_Cost!$B$1 -> 0 | AA25: Y
D26: 0.6.4 InfoSec|Application Security Enrollment and Testing | E26: 0.6.4.1 This includes the applicable enrollment and testing, such as SAST, DAST, Pen-Test, Privacy Scan, Mobile Shield and etc. | G26: Security | H26: 0.6.4.1 这包括适用的注册和测试，例如 SAST、DAST、渗透测试、隐私扫描、移动防护等。 | Q26: =BRD_EPIC2[[#This Row],[system type]]&BRD_EPIC2[[#This Row],[system type2]] | V26: =$U26*DE_Cost!$B$1*8 -> 0 | W26: =$U26*DE_Cost!$B$1 -> 0 | AA26: Y
D27: 0.6.5 InfoSec|Security Operation Monitoring and Verificiation | E27: 0.6.5.1 This includes: Network Connection Review (Firewall); Endpoint Security Verification and Testing; Scripting for MyJira Sync; Review Application Hosting and Cloud Infrastructure SCS; Vulnerability Scanning. | G27: Security | H27: 0.6.5.1 这包括：网络连接审查（防火墙）；终端安全验证和测试；MyJira Sync 的脚本编写；审查应用程序托管和云基础设施 SCS；漏洞扫描。 | Q27: =BRD_EPIC2[[#This Row],[system type]]&BRD_EPIC2[[#This Row],[system type2]] | U27: 0 | V27: =$U27*DE_Cost!$B$1*8 -> 0 | W27: =$U27*DE_Cost!$B$1 -> 0 | AA27: Y
D28: 0.6.6 InfoSec|Identity and Access Management | E28: 0.6.6.1 Integration with central authentication and authorization platforms. | G28: Security | H28: 0.6.6.1 与中央身份验证和授权平台的集成。 | Q28: =BRD_EPIC2[[#This Row],[system type]]&BRD_EPIC2[[#This Row],[system type2]] | V28: =$U28*DE_Cost!$B$1*8 -> 0 | W28: =$U28*DE_Cost!$B$1 -> 0 | AA28: Y
D29: 0.6.7 InfoSec|Online Fraud Detection | E29: 0.6.7.1 Online fraud rules review and integration with AOFD platform | G29: Security | H29: 0.6.7.1 在线欺诈规则审查并与 AOFD 平台集成 | Q29: =BRD_EPIC2[[#This Row],[system type]]&BRD_EPIC2[[#This Row],[system type2]] | V29: =$U29*DE_Cost!$B$1*8 -> 0 | W29: =$U29*DE_Cost!$B$1 -> 0 | AA29: Y
D30: 0.6.8 InfoSec|Disaster Recovery and Business Continuity Management | E30: 0.6.8.1 Conduct a Business Impact Analysis (BIA) to identify critical IT services and determine the IT service continuity strategy. Develop and test comprehensive IT Service Continuity Plans to maintain business operations in the event of security incidents or system downtime | G30: Security | H30: 0.6.8.1 进行业务影响分析（BIA）以识别关键 IT 服务并确定 IT 服务连续性策略。制定并测试全面的 IT 服务连续性计划，以在发生安全事件或系统停机时维持业务运营。 | Q30: =BRD_EPIC2[[#This Row],[system type]]&BRD_EPIC2[[#This Row],[system type2]] | V30: =$U30*DE_Cost!$B$1*8 -> 0 | W30: =$U30*DE_Cost!$B$1 -> 0 | AA30: Y
C31: 0.7 EA|Enterprise Architecture | D31: 0.7.1 EA|Solution Architecture Review | E31: 0.7.1.1 Collaborative work for appropriate design of availability, resilience, integrations and ensure all EA standards are aligned and complied | G31: EA | H31: 0.7.1.1 协同工作，确保可用性、弹性、集成设计的合理性，并确保所有企业架构标准保持一致并得到遵守 | Q31: =BRD_EPIC2[[#This Row],[system type]]&BRD_EPIC2[[#This Row],[system type2]] | V31: =$U31*DE_Cost!$B$1*8 -> 0 | W31: =$U31*DE_Cost!$B$1 -> 0 | AA31: Y
C32: 0.8 F&IT|Data Technology | D32: 0.8.1 Data|Database deployment on-premises | E32: 0.8.1.1 Database deploy on-premises, database schema changes, data migration and database optimization | G32: FIT | H32: 0.8.1.1 本地数据库部署、数据库架构变更、数据迁移和数据库优化 | Q32: =BRD_EPIC2[[#This Row],[system type]]&BRD_EPIC2[[#This Row],[system type2]] | V32: =$U32*DE_Cost!$B$1*8 -> 0 | W32: =$U32*DE_Cost!$B$1 -> 0 | AA32: Y
D33: 0.8.2 Data|Database deployment in cloud | E33: 0.8.2.1 Database deploy in cloud database schema changes, data migration and database optimization | G33: FIT | H33: 0.8.2.1 数据库部署在云数据库模式变更、数据迁移和数据库优化 | Q33: =BRD_EPIC2[[#This Row],[system type]]&BRD_EPIC2[[#This Row],[system type2]] | V33: =$U33*DE_Cost!$B$1*8 -> 0 | W33: =$U33*DE_Cost!$B$1 -> 0 | AA33: Y
D34: 0.8.3 Data|Data migration & synchronization | E34: 0.8.3.1 During the transition between the old POS and the new POS, the old POS data needs to be migrated to the New POS. Historical data from the past six months will be migrated in one batch. Incremental data will be synchronized in near real-time (within 15 minutes). Currently, there are three proposed solutions (choose one): Directly connect to the old POS database in the cloud or migrate the old POS sales data tables as-is into the New POS database, with the New POS handling the old tables’ data for interface display. Based on option 1, transform the data into the New POS format and write it into the New POS sales tables. Directly use Javis APIs to query old POS sales data to support order data inquiries, refunds, and exchange/return operations. 0.8.3.1 新老POS切换期间，需要将老POS数据迁移至New POS里，历史近半年数据一次性迁移，增量数据近实时同步（15分钟内）。目前有三种方案（选其一）： 1. 云上直连老POS数据库或将老POS的销售数据表原样迁移至New POS的库中，由New POS处理老表数据用于界面展示 2. 在1的基础上，将数据转换成New POS的数据，写入到New POS的销售表里 3. 直接使用Javis的接口查询老POS销售数据，完成订单数据查询、退款、退换货操作 | G34: Data & Jarvis | H34: 0.8.3.1 在旧 POS 系统和新 POS 系统过渡期间，旧 POS 数据需要迁移到新 POS 系统。 过去六个月的历史数据将一次性迁移。 增量数据将进行近实时同步（15 分钟内）。 目前，提出了三种解决方案（选择其一）： 直接连接到云端的旧 POS 数据库，或将旧 POS 销售数据表原样迁移到新 POS 数据库中，由新 POS 处理这些旧表的数据以进行界面显示。 根据选项 1，将数据转换为新的 POS 格式并写入新的 POS 销售表中。 直接使用 Javis API 查询旧的 POS 销售数据，以支持订单数据查询、退款以及换货/退货操作。 | K34: Jarvis | Q34: =BRD_EPIC2[[#This Row],[system type]]&BRD_EPIC2[[#This Row],[system type2]] | V34: =$U34*DE_Cost!$B$1*8 -> 0 | W34: =$U34*DE_Cost!$B$1 -> 0 | AA34: Y
A35: 1(Minimum scope) | B35: 2. Foundation operational functions 基础运营功能 | C35: 2.1 Merch & FnB product ordering 商品&餐饮点单 | D35: 2.1.1 [Merch] Add/delete product|Add product to shopping list 添加商品 | E35: 2.1.1.1 As Merch cashier, I need New POS will be able to add product to shopping list by barcode scanning or tap button, as to process shopping in store ordering. | F35: Items in one transaction may more than one thousand lines. | H35: 2.1.1.1 作为收银员，我需要新 POS 系统能够通过条形码扫描或点击按钮将商品添加到购物清单，以便处理店内购物订单。 | I35: 一个交易中的商品可能超过一千行。 | N35: 购物清单-添加+清单联动 | O35: 不包含优惠券等促销计算逻辑（需其他EPIC计算工时间） | P35: Android | Q35: =BRD_EPIC2[[#This Row],[system type]]&BRD_EPIC2[[#This Row],[system type2]] -> Android & QA & PM & DM & UI | R35: & QA & PM & DM & UI | U35: 5 | V35: =$U35*DE_Cost!$B$1*8 -> 48 | W35: =$U35*DE_Cost!$B$1 -> 6 | X35: 0 | Y35: 0 | Z35: =LEN(Q35) - LEN(SUBSTITUTE(Q35, "&", "")) + 1 -> 5 | AA35: =LEN(R35) - LEN(SUBSTITUTE(R35, "&", "")) + 1 -> 5 | AB35: =LEN(S35) - LEN(SUBSTITUTE(S35, "&", "")) + 1 -> 1 | AC35: =LEN(T35) - LEN(SUBSTITUTE(T35, "&", "")) + 1 -> 1
A36: 1(Minimum scope) | B36: 2. Foundation operational functions 基础运营功能 | C36: 2.1 Merch & FnB product ordering 商品&餐饮点单 | D36: 2.1.1 [Merch] Add/delete product|Delete product in shopping list 删除商品 | E36: 2.1.1.2 As Merch cashier, I need New POS will be able to delete product in shopping list by slide w/ tap button, as to process shopping in store ordering. | H36: 2.1.1.2 作为收银员，我需要新 POS 系统能够通过滑动并点击按钮来删除购物清单中的商品，以便处理店内订单购物。 | N36: 购物清单-删除 | O36: (删除（0.5天） | P36: Android | Q36: =BRD_EPIC2[[#This Row],[system type]]&BRD_EPIC2[[#This Row],[system type2]] -> Android & QA & PM & DM & UI | R36: & QA & PM & DM & UI | U36: 2 | V36: =$U36*DE_Cost!$B$1*8 -> 19.2 | W36: =$U36*DE_Cost!$B$1 -> 2.4 | X36: 0 | Y36: 0 | Z36: =LEN(Q36) - LEN(SUBSTITUTE(Q36, "&", "")) + 1 -> 5 | AA36: Y
A37: 1(Minimum scope) | B37: 2. Foundation operational functions 基础运营功能 | C37: 2.1 Merch & FnB product ordering 商品&餐饮点单 | D37: 2.1.1 [Merch] Add/delete product|Modify product quantity/price in shopping list 修改商品数量或价格 | E37: 2.1.1.3 As Merch cashier, I need New POS will be able to modify product quantity/price in shopping list by tap button , as to process shopping in store ordering. | F37: 1. Press “+, -” or entering number to adjust item quantity 2. Repeated scanning same item or continuous scanning in X seconds will accumulate quantity(X is configurable) 3. Pricing change can only be process by GSM/Lead authorized, and not impact its price in foundation data. GSM/Lead authorized needed. | H37: 2.1.1.3 作为收银员，我需要新 POS 系统能够通过点击按钮修改购物清单中的产品数量/价格，以便处理店内订单购物。 | I37: 1. 按“+、-”或输入数字调整商品数量 2. 在X秒内重复扫描同一商品或连续扫描将累积数量（X可配置） 3. 价格更改只能由GSM/主管授权处理，且不影响基础数据中的价格。需要GSM/主管授权。 | N37: 购物清单-修改-产品数量/价格 | O37: 1.权限校验 2.修改发起授权（弹窗输入主管工号/密码？这个功能应该是有单独工时跟进） | P37: Android | Q37: =BRD_EPIC2[[#This Row],[system type]]&BRD_EPIC2[[#This Row],[system type2]] -> Android & QA & PM & DM & UI | R37: & QA & PM & DM & UI | U37: 2 | V37: =$U37*DE_Cost!$B$1*8 -> 19.2 | W37: =$U37*DE_Cost!$B$1 -> 2.4 | X37: 0 | Y37: 0 | Z37: =LEN(Q37) - LEN(SUBSTITUTE(Q37, "&", "")) + 1 -> 5 | AA37: Y
A38: 1(Minimum scope) | B38: 2. Foundation operational functions 基础运营功能 | C38: 2.1 Merch & FnB product ordering 商品&餐饮点单 | D38: 2.1.1 [Merch] Add/delete product|Save/get product in shopping list 暂存与提取购物清单 | E38: 2.1.1.4 As Merch cashier, I need New POS will be able to save/get product list as draft when guest would like to order pending, as to process shopping in store ordering. | F38: 1. Modify draft shopping list: item/discount/coupon, and search 2. Delete shopping list | H38: 2.1.1.4 作为收银员，我需要新 POS 系统能够在客人想要暂存订单时保存/获取产品清单草稿，以便处理店内购物订单。 | I38: 1. 修改草稿购物车：商品/折扣/优惠券，以及搜索 2. 删除购物车 | N38: 购物清单-修改 | O38: 1.Android本地修改 2.销售信息联动，存在系统对接。实时试算。主要耗时在联调上(2)。 | P38: Android & Back-End | Q38: =BRD_EPIC2[[#This Row],[system type]]&BRD_EPIC2[[#This Row],[system type2]] -> Android & Back-End & QA & PM & DM & UI | R38: & QA & PM & DM & UI | U38: 5 | V38: =$U38*DE_Cost!$B$1*8 -> 48 | W38: =$U38*DE_Cost!$B$1 -> 6 | X38: 0 | Y38: 0 | Z38: =LEN(Q38) - LEN(SUBSTITUTE(Q38, "&", "")) + 1 -> 6 | AA38: Y
A39: 1(Minimum scope) | B39: 2. Foundation operational functions 基础运营功能 | C39: 2.1 Merch & FnB product ordering 商品&餐饮点单 | D39: 2.1.1 [Merch] Add/delete product|Check product saleable in shopping list 检查商品售卖状态 | E39: 2.1.1.5 As Merch cashier, I need New POS will be able to check product saleable when add into shopping list, display message when its unsaleable , as to make sure non-saleable product in shopping list. | F39: Finance | H39: 2.1.1.5 作为收银员，我需要新 POS 系统能够在商品添加到购物清单时检查其是否可销售，并在不可销售时显示提示信息，以确保购物清单中不会包含不可销售的商品。 | I39: 财务 | N39: 购物清单-添加时校验商品可用状态 | O39: 商品售卖状态在初始化时售卖状态应该拿到，直接校验（0.5） | P39: Android | Q39: =BRD_EPIC2[[#This Row],[system type]]&BRD_EPIC2[[#This Row],[system type2]] -> Android & QA & PM & DM & UI | R39: & QA & PM & DM & UI | U39: 2 | V39: =$U39*DE_Cost!$B$1*8 -> 19.2 | W39: =$U39*DE_Cost!$B$1 -> 2.4 | X39: 0 | Y39: 0 | Z39: =LEN(Q39) - LEN(SUBSTITUTE(Q39, "&", "")) + 1 -> 5 | AA39: Y
A40: 1(Minimum scope) | B40: 2. Foundation operational functions 基础运营功能 | C40: 2.1 Merch & FnB product ordering 商品&餐饮点单 | D40: 2.1.2 [FnB] QSR ordering|Ordering with add/delete meal on QSR 开单与添加删除商品 | E40: 2.1.2.1 As FnB cashier, I need New POS will be able to add/delete meal to shopping list by barcode scanning or tap button, as to process shopping in restaurant ordering. | F40: 1. Add single item/meal/service to list. 2. Delete product in shopping list. | H40: 2.1.2.1 作为餐饮收银员，我需要新 POS 系统能够通过条形码扫描或点击按钮来添加/删除购物清单中的餐品，以便处理餐厅订单。 | I40: 1. 将单个商品/餐点/服务添加到列表。 2. 删除购物车中的产品。 | N40: 购物清单-添加+清单联动 | O40: 扫码触发逻辑、增删查同步、本地缓存 不包含硬件集成 | P40: Android | Q40: =BRD_EPIC2[[#This Row],[system type]]&BRD_EPIC2[[#This Row],[system type2]] -> Android & QA & PM & DM & UI | R40: & QA & PM & DM & UI | U40: 5 | V40: =$U40*DE_Cost!$B$1*8 -> 48 | W40: =$U40*DE_Cost!$B$1 -> 6 | X40: 0 | Y40: 0 | Z40: =LEN(Q40) - LEN(SUBSTITUTE(Q40, "&", "")) + 1 -> 5 | AA40: N | AB40: 推荐5人天, 见2.1.1.1
A41: 1(Minimum scope) | B41: 2. Foundation operational functions 基础运营功能 | C41: 2.1 Merch & FnB product ordering 商品&餐饮点单 | D41: 2.1.2 [FnB] QSR ordering|Modify meal/set/Condiments configuration 调整单品、套餐与调料 | E41: 2.1.2.2 As FnB cashier, I need New POS will be able to modify meal/set/condiments configuration in shopping list, as to process shopping in restaurant ordering. | F41: Sync to kitchen printer for order detail. Condiments may deduct inventory or not deduct(depending on the case) | H41: 2.1.2.2 作为餐饮收银员，我需要新 POS 系统能够在购物清单中修改餐食/套餐/调味品配置，以便处理餐厅订单的购物流程。 | I41: 同步到厨房打印机以获取订单详情。 调味品可能会扣除库存，也可能不扣除（视情况而定） | N41: 购物清单-获取厨房订单信息 | O41: 配置的增删改查开发（2） 可视库存检查（1） 【无库存概念，部分餐饮有可售库存（不在这里估），打印同步不在这里估】 | P41: Android & Back-End | Q41: =BRD_EPIC2[[#This Row],[system type]]&BRD_EPIC2[[#This Row],[system type2]] -> Android & Back-End & QA & PM & DM & UI | R41: & QA & PM & DM & UI | U41: 3 | V41: =$U41*DE_Cost!$B$1*8 -> 28.8 | W41: =$U41*DE_Cost!$B$1 -> 3.6 | X41: 0 | Y41: 0 | Z41: =LEN(Q41) - LEN(SUBSTITUTE(Q41, "&", "")) + 1 -> 6 | AA41: Y
...

Sheet 1_Standard Part
A1: No. 序号 | B1: Quotation Item 报价项 | C1: Description 内容说明 | D1: Unit 计费单位 | E1: Quantity 数量 | F1: Unit Price(VAT Inc) 含税单价 | G1: Total Price(VAT Inc) 含税总价 | H1: Tax Rate 税率 | I1: Filling Instructions 填写说明
A2: =ROW()-1 -> 1 | B2: Standard Software 标品软件 | C2: 1. Deploy the standard software server and client in Party A’s own environment. 2. Provide a complete user manual. 3. Provide functional specification documentation for the standard software. 4. Deliver the full source code, including source code files, architecture description, deployment documents, test cases, training materials, and all other deliverables covering the software development lifecycle. 1. 在甲方自有环境部署标品软件服务端和客户端 2. 提供软件完整操作手册 3. 提供标品软件功能说明文档 4. 提供完整源码交付：含源码、架构说明、部署文档、测试用例、培训材料等软件生命周期的所有交付材料 Comments: The acquisition of the source code is solely intended for internal use and dedicated to expanding functionalities through development. We assure that it will not be utilized for any commercial purposes. 注：源码的购买仅用于内部功能扩展开发使用，承诺不用于任何商业用途。 | D2: 套 | E2: 1 | F2: 4420000 | G2: =E2*F2 -> 4420000 | H2: 0.06 | I2: Please fill in the quantity, unit price (tax included), and tax rate. The total price (tax included) will be auto-calculated; no need to fill it in. For non-standard software, please enter 0 for the quantity. 请填写数量，含税单价，税率 含税总价不需要填写，自动生成 无标品软件提供的，数量填0 有标品软件，请填写单位(如套)
A3: 标品软件包含RFP功能列表
A4: No. 序号 | B4: RFP Section RFP章节 | C4: Function Module 功能模块 | D4: Function Name 功能名称 | E4: Filling Instructions 填写说明 | F4: EPIC | G4: Time spent by EPIC | H4: price | I4: 公式例子
A5: =ROW()-4 -> 1 | B5: 3.2.1.1 3.2.2.1 3.2.4.1 3.2.5.1 3.2.6.1 | C5: Account Log-in 账号 | D5: Log-in/Log out Change Password修改密码 Lock Account | E5: 刷卡登录功能需要定制化 | F5: 2.8.3.1 2.8.3.2 2.8.3.3 2.8.3.4 | I5: count day总和 985 价格公式例子 91/所有的总和*4420000 注意此处EPIC的编号重复，内容不一样
A6: =ROW()-4 -> 2 | B6: 3.2.1.2 3.2.2.2 3.2.4.2 3.2.5.2 3.2.6.2 | C6: Store Open/Closed 开关店 | D6: Store Open开店 Store Close 关店 | F6: 2.6.1.1 2.6.1.2 2.6.1.7 2.6.2.1 | I6: 3.2.2.2 中应急支付
A7: =ROW()-4 -> 3 | B7: 3.2.1.3 3.2.4.3 3.2.5.3 3.2.6.3 | C7: Product Item Management 商品项管理 | D7: Menu Management菜单管理 Search 餐品查询 Product Modify商品编辑 | F7: 2.7.1.3
A8: =ROW()-4 -> 4 | B8: 3.2.6.4 | C8: Table Management 桌台管理 | D8: Table Management桌台管理 Open Table开桌台 | F8: 2.6.1.6 2.1.3.1 2.1.3.2 2.1.3.6 2.3.2.4
A9: =ROW()-4 -> 5 | B9: 3.2.1.5 3.2.2.5 3.2.4.5 3.2.5.5 3.2.6.6 | C9: Order 订单操作 | D9: Create Order创建订单 Settlement结算 Order Landing落单 Store Pickup门店自提 | F9: 2.1.1.1 2.1.1.2 2.1.1.3 2.1.1.4 2.1.2.1 2.1.2.2 2.1.2.3 2.1.2.4 2.1.2.5 2.2.2.1 2.2.2.2 2.2.2.4 2.3.1.1 2.3.1.2 2.3.1.3 2.3.1.4 2.3.1.5 2.3.2.1 2.3.2.2 2.3.2.3 2.3.2.4
A10: =ROW()-4 -> 6 | B10: 3.2.1.6 3.2.2.6 3.2.3.3 3.2.4.6 3.2.5.6 3.2.6.7 3.2.7.3 | C10: Order Management 订单管理 | D10: Return退货 Exchange换货 Suspend Order挂单 Search 查询 | F10: 2.4.3.2 2.4.3.3 2.4.2.1 2.4.2.2
A11: =ROW()-4 -> 7 | B11: 3.2.3.1 3.2.7.1 3.2.3.4 | C11: Online Order Creation 线上订单创建 Exception handling on order integration 异常处理 | D11: Master data sychonization and validation餐品主档同步和餐品校验 Previlege Validation权益校验 Order Payment订单支付 Exception handling on order integration 异常处理 | F11: 2.4.1.1 2.4.1.2 2.4.1.3 2.4.1.4 2.4.1.5 3.6.4.1 3.6.5.1
A12: =ROW()-4 -> 8 | B12: 3.2.8 | C12: Merch and F&B Cross-sell Stores 商品&餐饮综合门店 | D12: 功能等同于以下两个功能模块 3.2.1 Merchandise Store零售门店 3.2.4 F&B Quick Service Resturant 餐饮快餐 | G12: 已标注等同位置
A13: =ROW()-4 -> 9 | B13: 3.2.9.1 3.2.9.3 3.2.9.4 | C13: Inventory Management 库存管理 | D13: Inventory Synchronization库存同步 Inventory Search库存查询 Inventory Monitor & Alert库存监控机制 | F13: 3.6.3.1 3.6.3.2 3.6.3.3
A14: =ROW()-4 -> 10 | B14: 3.2.10.1 3.2.10.2 3.2.10.3 3.2.10.4 | C14: Product Management 商品管理 | D14: Product Creation商品创建 Master Data Management 商品主档信息管理 Product Search & Product List商品查询&商品列表 Monitoring and Alert监控和预警 | F14: 2.7.1.1 2.7.1.2 2.7.1.4 2.7.1.5 | G14: Customize Part 中重复
A15: =ROW()-4 -> 11 | B15: 3.2.11.1 3.2.11.2 3.2.11.3 3.2.11.4 3.2.11.5 | C15: Promotion Management 促销管理 | D15: Promotion Creation创建促销 Promotion Types 促销类型 Promotion List促销列表 Promotion Quota Control促销额度管理 Promotion Rules Setting促销规则管理 | F15: 2.2.1.1 2.2.1.2 2.2.1.3
A16: =ROW()-4 -> 12 | B16: 3.2.13 | C16: System Admin 系统管理 | D16: 3.2.13.1 ~ 3.2.13.9的功能 | F16: 2.8.2.1 2.8.2.2 2.8.2.3 2.8.3.1 2.8.3.4 2.9.2.3 2.9.2.4 2.5.1.1 2.6.3.1 2.6.3.2 2.6.3.3 3.4.1.1 3.4.1.2 3.4.1.4 3.4.2.1 3.4.2.2 3.4.3.1 3.4.3.2 3.4.4.1 3.4.5.1 3.5.2.1 3.5.2.2 5.1.2.1 | I16: 2.8.3.1 2.8.3.2 2.8.3.3 2.8.3.4 在EPIC中重复号，需要看内容才能理解

Sheet 2_Customize Part
A1: Additional Notes： 补充说明： | B1: The custom development section includes function adaptation, custom feature development, and integration with SHDR’s internal systems. 定制开发部分包含功能适配、功能开发、SHDR内部系统对接等。
A2: No. 序号 | B2: RFP Section RFP章节 | C2: Function Module 功能模块 | D2: Function Name 功能名称 | E2: Workload (Man-Days) 工作量（人天） | F2: Unit Price(VAT Inc) 含税单价 | G2: Total Price(VAT Inc) 含税总价 | H2: Tax Rate 税率 | I2: Filling Instructions 填写说明 | J2: EIPC | K2: day
A3: =ROW()-2 -> 1 | B3: 3.2.1.1 3.2.4.1 3.2.5.1 3.2.6.1 | C3: User Account 账号 | D3: Slash card 刷卡登录 | E3: 30 | F3: 2611 | G3: =E3*F3 -> 78330 | H3: 0.06 | J3: 2.8.3.2
A4: =ROW()-2 -> 2 | B4: 3.2.1.2 3.2.4.2 3.2.5.2 3.2.6.2 | C4: Store Open/Closed 开关店 | D4: POS Support offline mode POS支持离线交易 查看钱箱报表 | E4: 30 | F4: 2611 | G4: =E4*F4 -> 78330 | H4: 0.06 | J4: 2.6.2.3 2.3.3.4
A5: =ROW()-2 -> 3 | B5: 3.2.1.3 3.2.4.3 3.2.5.3 3.2.6.3 | C5: Product Items Management 商品项管理 | D5: Search Functions 搜索功能 Store inventory view and editing require authurization 门店库存的查看和编辑需要授权 | E5: 25 | F5: 2611 | G5: =E5*F5 -> 65275 | H5: 0.06 | J5: 3.5.1.1 2.6.1.7
A6: =ROW()-2 -> 4 | B6: 3.2.6.4.1 | C6: Table Management 桌台管理 | D6: Reservation 预定信息 | E6: 25 | F6: 2611 | G6: =E6*F6 -> 65275 | H6: 0.06 | J6: 3.1.2.4
A7: =ROW()-2 -> 5 | B7: 3.2.1.4 3.2.4.4 3.2.5.4 3.2.6.5 | C7: Guest Profile 游客身份识别 | D7: Log in登录 Profile Display显示游客身份信息 Previlege Recommendation权益推荐 Black List黑名单 | E7: 30 | F7: 2611 | G7: =E7*F7 -> 78330 | H7: 0.06
A8: =ROW()-2 -> 6 | B8: 3.2.2.5.1 | C8: Order Operation 订单操作 | D8: RFID Add product RFID添加商品 Modify Price 修改价格 Modify Inventory 修改库存 | E8: 55 | F8: 2611 | G8: =E8*F8 -> 143605 | H8: 0.06 | J8: 3.6.6.2
A9: =ROW()-2 -> 7 | B9: 3.2.1.6.5 3.2.3.4 3.2.4.6.4 3.2.5.6.4 3.2.6.7.4 3.2.6.7.5 3.2.7.4 | C9: Order Management 订单管理 | D9: Order Transmit 订单下发 Check & Order Modify 订单&账单编辑 | E9: 30 | F9: 2611 | G9: =E9*F9 -> 78330 | H9: 0.06 | J9: 2.4.1.1 2.4.1.2 2.4.1.3 2.4.1.4
A10: =ROW()-2 -> 8 | B10: 3.2.3.2 3.2.7.2 | C10: Order Landing 落单 | D10: Order Landing 落单 | E10: 25 | F10: 2611 | G10: =E10*F10 -> 65275 | H10: 0.06 | J10: 3.6.2.1 3.6.2.2 3.6.2.3
A11: =ROW()-2 -> 9 | B11: 3.2.1.7 3.2.4.7 3.2.5.7 3.2.6.8 | C11: Hardware Peripherals 硬件外设 | D11: Hardware Peripherals 硬件外设 | E11: 85 | F11: 2611 | G11: =E11*F11 -> 221935 | H11: 0.06 | J11: 2.9.1.3
A12: =ROW()-2 -> 10 | B12: 3.2.9.2 | C12: Inventory Management 库存管理 | D12: Store Repleishment 店间补货 Warehouse Repleishment 仓库补货 (产品安全溯源系统) | E12: 30 | F12: 2611 | G12: =E12*F12 -> 78330 | H12: 0.06 | J12: 3.6.3.1 3.5.2.2
A13: =ROW()-2 -> 11 | B13: 3.2.10.5 | C13: Product Management 商品管理 | D13: Configuration 功能配置 | H13: 0.06 | J13: 2.7.1.3
A14: =ROW()-2 -> 12 | B14: 3.2.10.1 3.2.10.2 3.2.10.3 3.2.10.4 | C14: Promotion Management 促销管理 | D14: Product Creation商品创建 Master Data Management 商品主档信息管理 Product Search & Product List商品查询&商品列表 Monitoring and Alert监控和预警 | H14: 0.06 | J14: 2.7.1.1 2.7.1.2 2.7.1.4 2.7.1.5
A15: =ROW()-2 -> 13 | B15: 3.2 | C15: Store Management 门店管理 | D15: Store Information Management 门店基础信息管理 | H15: 0.06 | J15: 2.6.1.5
A16: =ROW()-2 -> 14 | B16: 3.2 | C16: Workstation Management 工作终端管理 | D16: POS Workstation Management POS终端管理 | E16: 30 | F16: 2611 | G16: =E16*F16 -> 78330 | H16: 0.06 | J16: 2.9.1.1 2.9.1.3
A17: =ROW()-2 -> 15 | B17: 3.2 | D17: Printer Setting 打印机设置 | H17: 0.06 | J17: 2.9.2.1 2.9.2.2
A18: =ROW()-2 -> 16 | B18: 3.2.12.1 | C18: POS Report POS 报表 | D18: Report Creation 创建报表 | H18: 0.06 | J18: 2.10.1.1 2.10.1.2 2.10.1.3
A19: =ROW()-2 -> 17 | B19: 3.2.12.2 | D19: Self-defined Report 自定义报表功能 | H19: 0.06 | J19: 2.11.4.1 2.11.4.2 2.11.4.3 2.11.4.5
A20: =ROW()-2 -> 18 | B20: 3.2.13.1 | C20: System Admin 系统管理 | D20: Role management 角色管理 | E20: 30 | F20: 2611 | G20: =E20*F20 -> 78330 | H20: 0.06 | J20: 2.8.3.1 2.8.2.4
A21: =ROW()-2 -> 19 | B21: 3.2.13.2 | D21: Account management 账号管理 | H21: 0.06 | J21: 2.8.3.2 2.8.3.3
A22: =ROW()-2 -> 20 | B22: 3.2.13.3 | D22: User Journal 操作日志管理 | H22: 0.06 | J22: 2.8.3.4
A23: =ROW()-2 -> 21 | B23: 3.3.5 | C23: System Integration Requirements 系统集成需求 | D23: Receive SIMBA pushes Product Data interface 接收SIMBA推送的 商品信息接口 | H23: 0.06 | J23: 3.6.1.1 3.6.1.2
A24: =ROW()-2 -> 22 | B24: 3.3.5 | C24: System Integration Requirements 系统集成需求 | D24: Inventory Query Interface 库存查询接口（Merch） | E24: 0 | G24: 0 | H24: 0.06 | J24: 3.6.1.3
A25: =ROW()-2 -> 23 | B25: 3.3.5 | C25: System Integration Requirements 系统集成需求 | D25: Create Order Interface 创建订单接口 | E25: 25 | F25: 2611 | G25: =E25*F25 -> 65275 | H25: 0.06
A26: =ROW()-2 -> 24 | B26: 3.3.5 | C26: System Integration Requirements 系统集成需求 | D26: Commodity Trading Push Interface 商品交易推送接口 | H26: 0.06
A27: =ROW()-2 -> 25 | B27: 3.3.5 | C27: System Integration Requirements 系统集成需求 | D27: POS Docking CCTV POS对接CCTV | E27: 130 | F27: 2611 | G27: =E27*F27 -> 339430 | H27: 0.06 | J27: 3.7.7.10
A28: =ROW()-2 -> 26 | B28: 3.3.5 | C28: System Integration Requirements 系统集成需求 | D28: Coupon Query Interface 券查询口 | H28: 0.06 | J28: 3.6.6.1
A29: =ROW()-2 -> 27 | B29: 3.3.5 | C29: System Integration Requirements 系统集成需求 | D29: Coupon Verification Interface 券核销接口 | E29: 25 | F29: 2611 | G29: =E29*F29 -> 65275 | H29: 0.06 | J29: 3.4.1.3
A30: =ROW()-2 -> 28 | B30: 3.3.5 | C30: System Integration Requirements 系统集成需求 | D30: Inventory Updates Interface 库存更新接口(F&B) | H30: 0.06 | J30: 3.5.1.1
A31: =ROW()-2 -> 29 | B31: 3.3.5 | C31: System Integration Requirements 系统集成需求 | D31: Invoicing Synchronous Interface 同步开票信息接口 | H31: 0.06 | J31: 3.7.5.1
A32: =ROW()-2 -> 30 | B32: 3.3.5 | C32: System Integration Requirements 系统集成需求 | D32: Store CostCenter Pushes the UDS Interface 门店成本中心推送UDS接口 | H32: 0.06
A33: =ROW()-2 -> 31 | B33: 3.3.5 | C33: System Integration Requirements 系统集成需求 | D33: 推送销售数据到UDS（SAP） | E33: 50 | F33: 2611 | G33: =E33*F33 -> 130550 | H33: 0.06
A34: =ROW()-2 -> 32 | B34: 3.3.5 | C34: System Integration Requirements 系统集成需求 | D34: 推送销售数据到UDS（LongView） | E34: 10 | F34: 2611 | G34: =E34*F34 -> 26110 | H34: 0.06
A35: =ROW()-2 -> 33 | B35: 3.3.5 | C35: System Integration Requirements 系统集成需求 | D35: 推送销售数据到UDS（Kornos） | E35: 28 | F35: 2611 | G35: =E35*F35 -> 73108 | H35: 0.06
A36: =ROW()-2 -> 34 | B36: 3.3.5 | C36: System Integration Requirements 系统集成需求 | D36: Employee Discount Information Push Interface 员工折扣信息推送接口 | E36: 45 | F36: 2611 | G36: =E36*F36 -> 117495 | H36: 0.06
A37: =ROW()-2 -> 35 | B37: 3.3.5 | C37: System Integration Requirements 系统集成需求 | D37: Inquire%Verify Member Information 查询验证会员信息 | E37: 15 | F37: 2611 | G37: =E37*F37 -> 39165 | H37: 0.06
A38: =ROW()-2 -> 36 | B38: 3.3.5 | C38: System Integration Requirements 系统集成需求 | D38: Inventory Updates Interface 库存更新接口(Merch) | E38: 10 | F38: 2611 | G38: =E38*F38 -> 26110 | H38: 0.06
A39: =ROW()-2 -> 37 | B39: 3.3.5 | C39: System Integration Requirements 系统集成需求 | D39: Order Placement Interface 订单落单接口 | E39: 10 | F39: 2611 | G39: =E39*F39 -> 26110 | H39: 0.06
A40: =ROW()-2 -> 38 | B40: 3.3.5 | C40: System Integration Requirements 系统集成需求 | D40: Order Query Interface 订单查询接口 | E40: 8 | F40: 2611 | G40: =E40*F40 -> 20888 | H40: 0.06
...

Sheet BRD & EPIC
A1: EPIC - Project Name | F1: 点击返回说明页 Back to Instructions | X1: 0 | AC1: 总金额 | AD1: 有效条数 | AE1: 总人天
A2: LOB VP Signature | C2: Tony Castillo/Steve Sulaski | D2: Date | AC2: 7378263 | AD2: =SUBTOTAL(103, P:P) - 1 -> 241 | AE2: =SUM(Y:Y) -> 20181
A3: PM Diretctor Level Sigature | C3: Jimmy Lee | D3: Date
A4: DM Diretctor Level Sigature | C4: Peter Zhang | D4: Date
A6: BRD Priority | B6: 0. BRD Overview | C6: 0.0 BRD Detailed Requirement | D6: 0.0.0 EPIC Title | E6: 0.0.0.0 EPIC Story | F6: Description | G6: Dependencies | H6: EPIC Story(CN) | I6: Description(CN) | J6: Comment | K6: Follow-up Group | L6: Follow-up | M6: Follow-up with vendor | N6: Task Title | O6: Task Description | P6: system type | Q6: follw up PM | R6: follow up | S6: Develop Labor(man/day) | T6: Real Develop Labor(Man/Hour) | U6: Real Develop Labor(Man/Day) | V6: 表设计 | W6: 表个数 | X6: task count | Y6: task sum count | Z6: Review Pass | AA6: Lucky Comment | AB6: check content change | AD6: Asset Function | AE6: 分摊到1条的钱数
A7: 0 | B7: 0. Project Foundation | C7: 0.1 SE|Hosting | D7: 0.1.1 SE|System deployment in Cloud | E7: 0.1.1.1 Services/systems set up in cloud, Create new cloud accounts, New vendor system support in Cloud | G7: SE | H7: 0.1.1.1 在云中设置的服务/系统，创建新的云账户，在云中支持新的供应商系统 | T7: =$S7*DE_Cost!$B$1*8 -> 0 | U7: =$S7*DE_Cost!$B$1 -> 0 | X7: =IF(TRIM(P7)="", 0, LEN(P7) - LEN(SUBSTITUTE(P7, "&", "")) + 1) -> 0 | Y7: =S7 * X7 -> 0 | Z7: Y | AE7: =(Y7 / $AE$2) * $AC$2 -> 0
D8: 0.1.2 SE|System deployment on-premise | E8: 0.1.2.1 Services/systems deployment/configurition/automation for new servers in on-premise datacenter | G8: SE | H8: 0.1.2.1 本地数据中心新服务器部署/配置/自动化服务/系统 | T8: =$S8*DE_Cost!$B$1*8 -> 0 | U8: =$S8*DE_Cost!$B$1 -> 0 | X8: =IF(TRIM(P8)="", 0, LEN(P8) - LEN(SUBSTITUTE(P8, "&", "")) + 1) -> 0 | Y8: =S8 * X8 -> 0 | Z8: Y | AE8: =(Y8 / $AE$2) * $AC$2 -> 0
D9: 0.1.3 SE|Database deployment in Cloud | E9: 0.1.3.1 Database set up in cloud, dashboard requirements, database schema changes, data migration | G9: SE | H9: 0.1.3.1 云端数据库设置，仪表板需求，数据库架构变更，数据迁移 | T9: =$S9*DE_Cost!$B$1*8 -> 0 | U9: =$S9*DE_Cost!$B$1 -> 0 | X9: =IF(TRIM(P9)="", 0, LEN(P9) - LEN(SUBSTITUTE(P9, "&", "")) + 1) -> 0 | Y9: =S9 * X9 -> 0 | Z9: Y | AE9: =(Y9 / $AE$2) * $AC$2 -> 0
D10: 0.1.4 SE|Cloud Hosting | E10: 0.1.4.1 Hosting fee in AliCloud, AWS | G10: SE | H10: 0.1.4.1 阿里云、AWS 托管费用 | T10: =$S10*DE_Cost!$B$1*8 -> 0 | U10: =$S10*DE_Cost!$B$1 -> 0 | X10: =IF(TRIM(P10)="", 0, LEN(P10) - LEN(SUBSTITUTE(P10, "&", "")) + 1) -> 0 | Y10: =S10 * X10 -> 0 | Z10: Y | AE10: =(Y10 / $AE$2) * $AC$2 -> 0
D11: 0.1.5 SE|Hardware purchase | E11: 0.1.5.1 New servers/storage/devices in on-premise datacenter | G11: SE | H11: 0.1.5.1 本地数据中心中的新服务器/存储设备 | T11: =$S11*DE_Cost!$B$1*8 -> 0 | U11: =$S11*DE_Cost!$B$1 -> 0 | X11: =IF(TRIM(P11)="", 0, LEN(P11) - LEN(SUBSTITUTE(P11, "&", "")) + 1) -> 0 | Y11: =S11 * X11 -> 0 | Z11: Y | AE11: =(Y11 / $AE$2) * $AC$2 -> 0
D12: 0.1.6 SE|Vendor Service | E12: 0.1.6.1 3rd party vendor services | G12: SE | H12: 0.1.6.1 第三方供应商服务 | T12: =$S12*DE_Cost!$B$1*8 -> 0 | U12: =$S12*DE_Cost!$B$1 -> 0 | X12: =IF(TRIM(P12)="", 0, LEN(P12) - LEN(SUBSTITUTE(P12, "&", "")) + 1) -> 0 | Y12: =S12 * X12 -> 0 | Z12: Y | AE12: =(Y12 / $AE$2) * $AC$2 -> 0
D13: 0.1.7 SE|License|Software | E13: 0.1.7.1 License cost for hardware/software | G13: SE | H13: 0.1.7.1 硬件/软件的许可费用 | T13: =$S13*DE_Cost!$B$1*8 -> 0 | U13: =$S13*DE_Cost!$B$1 -> 0 | X13: =IF(TRIM(P13)="", 0, LEN(P13) - LEN(SUBSTITUTE(P13, "&", "")) + 1) -> 0 | Y13: =S13 * X13 -> 0 | Z13: Y | AE13: =(Y13 / $AE$2) * $AC$2 -> 0
C14: 0.2 QO|GQE | D14: 0.2.1 GQE |Manual Testing | E14: 0.2.1.1 Design test cases, execute test cases, analyze defects, write test reports for Manual Testing. | G14: QO | H14: 0.2.1.1 设计测试用例，执行测试用例，分析缺陷，编写手动测试报告。 | K14: QO | T14: =$S14*DE_Cost!$B$1*8 -> 0 | U14: =$S14*DE_Cost!$B$1 -> 0 | X14: =IF(TRIM(P14)="", 0, LEN(P14) - LEN(SUBSTITUTE(P14, "&", "")) + 1) -> 0 | Y14: =S14 * X14 -> 0 | Z14: Y | AE14: =(Y14 / $AE$2) * $AC$2 -> 0
D15: 0.2.2 GQE |Automation Testing | E15: 0.2.2.1 Design test cases, encode test cases, execute automation scripts, analyze defects, write test reports for Automation Testing. | G15: QO | H15: 0.2.2.1 设计测试用例，编码测试用例，执行自动化脚本，分析缺陷，编写自动化测试报告。 | K15: QO | T15: =$S15*DE_Cost!$B$1*8 -> 0 | U15: =$S15*DE_Cost!$B$1 -> 0 | X15: =IF(TRIM(P15)="", 0, LEN(P15) - LEN(SUBSTITUTE(P15, "&", "")) + 1) -> 0 | Y15: =S15 * X15 -> 0 | Z15: Y | AE15: =(Y15 / $AE$2) * $AC$2 -> 0
D16: 0.2.3 GQE |Performance Testing | E16: 0.2.3.1 Design test cases, encode test cases, execute performance test cases, analyze defects, write test reports for Performance Testing. | G16: QO | H16: 0.2.3.1 设计测试用例，编码测试用例，执行性能测试用例，分析缺陷，编写性能测试报告。 | K16: QO | T16: =$S16*DE_Cost!$B$1*8 -> 0 | U16: =$S16*DE_Cost!$B$1 -> 0 | X16: =IF(TRIM(P16)="", 0, LEN(P16) - LEN(SUBSTITUTE(P16, "&", "")) + 1) -> 0 | Y16: =S16 * X16 -> 0 | Z16: Y | AE16: =(Y16 / $AE$2) * $AC$2 -> 0
D17: 0.2.4 GQE |Command Center Support | E17: 0.2.4.1 Support command centers during launch and hypercare period. | G17: QO | H17: 0.2.4.1 在发布和超保支持期间支持指挥中心。 | K17: QO | T17: =$S17*DE_Cost!$B$1*8 -> 0 | U17: =$S17*DE_Cost!$B$1 -> 0 | X17: =IF(TRIM(P17)="", 0, LEN(P17) - LEN(SUBSTITUTE(P17, "&", "")) + 1) -> 0 | Y17: =S17 * X17 -> 0 | Z17: Y | AE17: =(Y17 / $AE$2) * $AC$2 -> 0
C18: 0.3 QO|Release Management | D18: 0.3.1 RM |Change and Release Support | E18: 0.3.1.1 Plan, design, schedule, validate, deploy and control system changes and releases to support system launches. | G18: QO | H18: 0.3.1.1 计划、设计、安排、验证、部署和控制系统变更与发布，以支持系统上线。 | K18: QO | T18: =$S18*DE_Cost!$B$1*8 -> 0 | U18: =$S18*DE_Cost!$B$1 -> 0 | X18: =IF(TRIM(P18)="", 0, LEN(P18) - LEN(SUBSTITUTE(P18, "&", "")) + 1) -> 0 | Y18: =S18 * X18 -> 0 | Z18: Y | AE18: =(Y18 / $AE$2) * $AC$2 -> 0
D19: 0.3.2 RM |Command Center Support | E19: 0.3.2.1 Support command centers during hypercare period. | G19: QO | H19: 0.3.2.1 在超保期间支持指挥中心。 | K19: QO | T19: =$S19*DE_Cost!$B$1*8 -> 0 | U19: =$S19*DE_Cost!$B$1 -> 0 | X19: =IF(TRIM(P19)="", 0, LEN(P19) - LEN(SUBSTITUTE(P19, "&", "")) + 1) -> 0 | Y19: =S19 * X19 -> 0 | Z19: Y | AE19: =(Y19 / $AE$2) * $AC$2 -> 0
C20: 0.4 QO|Incident Management | D20: 0.4.1 L2 |Configuration Management | E20: 0.4.1.1 Perform configuration changes on TYK, ACP, UAP, VDM. | G20: QO | H20: 0.4.1.1 在 TYK、ACP、UAP、VDM 上执行配置更改。 | J20: 确认Onsite时间， L2需要规划成员支持 7天，7:~23 | K20: QO | T20: =$S20*DE_Cost!$B$1*8 -> 0 | U20: =$S20*DE_Cost!$B$1 -> 0 | X20: =IF(TRIM(P20)="", 0, LEN(P20) - LEN(SUBSTITUTE(P20, "&", "")) + 1) -> 0 | Y20: =S20 * X20 -> 0 | Z20: Y | AE20: =(Y20 / $AE$2) * $AC$2 -> 0
D21: 0.4.2 L2 |Command Center Coordination and Support | E21: 0.4.2.1 Plan and implement command centers to support launches. | G21: QO | H21: 0.4.2.1 规划并实施支持发射的指挥中心。 | J21: 确认try run时间，住酒店40人/1000 | K21: QO | T21: =$S21*DE_Cost!$B$1*8 -> 0 | U21: =$S21*DE_Cost!$B$1 -> 0 | X21: =IF(TRIM(P21)="", 0, LEN(P21) - LEN(SUBSTITUTE(P21, "&", "")) + 1) -> 0 | Y21: =S21 * X21 -> 0 | Z21: Y | AE21: =(Y21 / $AE$2) * $AC$2 -> 0
C22: 0.5 QO|Problem Management | D22: 0.5.1 Problem Management |Proactive Problem Management | E22: 0.5.1.1 Follow all opened defects that will move to production with the launch and drive the resolution of defects before they turn into incidents. | G22: QO | H22: 0.5.1.1 跟踪所有将随发布移至生产环境的缺陷，并在其演变为事件前推动解决这些缺陷。 | J22: 需要确认我们自己是否介入测试 | K22: QO | T22: =$S22*DE_Cost!$B$1*8 -> 0 | U22: =$S22*DE_Cost!$B$1 -> 0 | X22: =IF(TRIM(P22)="", 0, LEN(P22) - LEN(SUBSTITUTE(P22, "&", "")) + 1) -> 0 | Y22: =S22 * X22 -> 0 | Z22: Y | AE22: =(Y22 / $AE$2) * $AC$2 -> 0
C23: 0.6 InfoSec|Information Security | D23: 0.6.1 InfoSec|Security Terms Review in the Contract | E23: 0.6.1.1 Whenever the 3rd party provider would like to change the default information security terms and schedules, the project team needs to contact InfoSec for change review. | G23: Security | H23: 0.6.1.1 当第三方提供商希望更改默认信息安全条款和时间表时，项目团队需要联系信息安全部门进行变更审核。 | T23: =$S23*DE_Cost!$B$1*8 -> 0 | U23: =$S23*DE_Cost!$B$1 -> 0 | X23: =IF(TRIM(P23)="", 0, LEN(P23) - LEN(SUBSTITUTE(P23, "&", "")) + 1) -> 0 | Y23: =S23 * X23 -> 0 | Z23: Y | AE23: =(Y23 / $AE$2) * $AC$2 -> 0
D24: 0.6.2 InfoSec|Information Security Assessment (ISA) | E24: 0.6.2.1 All the new applications and significant change to the existing applications need to complete the information security assessment. | G24: Security | H24: 0.6.2.1 所有新应用及对现有应用的重大变更均需完成信息安全评估。 | T24: =$S24*DE_Cost!$B$1*8 -> 0 | U24: =$S24*DE_Cost!$B$1 -> 0 | X24: =IF(TRIM(P24)="", 0, LEN(P24) - LEN(SUBSTITUTE(P24, "&", "")) + 1) -> 0 | Y24: =S24 * X24 -> 0 | Z24: Y | AE24: =(Y24 / $AE$2) * $AC$2 -> 0
D25: 0.6.3 InfoSec|RFP Security Questionnaire and/or Third Party Assessment (TPA) | E25: 0.6.3.1 If a 3rd party provider is involved, RFP security questionnaire is mandatory to be filled, and if necessary the Third Party Assessment should be conducted. | G25: Security | H25: 0.6.3.1 如果涉及第三方供应商，则必须填写 RFP 安全问卷，并在必要时进行第三方评估。 | T25: =$S25*DE_Cost!$B$1*8 -> 0 | U25: =$S25*DE_Cost!$B$1 -> 0 | X25: =IF(TRIM(P25)="", 0, LEN(P25) - LEN(SUBSTITUTE(P25, "&", "")) + 1) -> 0 | Y25: =S25 * X25 -> 0 | Z25: Y | AE25: =(Y25 / $AE$2) * $AC$2 -> 0
D26: 0.6.4 InfoSec|Application Security Enrollment and Testing | E26: 0.6.4.1 This includes the applicable enrollment and testing, such as SAST, DAST, Pen-Test, Privacy Scan, Mobile Shield and etc. | G26: Security | H26: 0.6.4.1 这包括适用的注册和测试，例如 SAST、DAST、渗透测试、隐私扫描、移动防护等。 | T26: =$S26*DE_Cost!$B$1*8 -> 0 | U26: =$S26*DE_Cost!$B$1 -> 0 | X26: =IF(TRIM(P26)="", 0, LEN(P26) - LEN(SUBSTITUTE(P26, "&", "")) + 1) -> 0 | Y26: =S26 * X26 -> 0 | Z26: Y | AE26: =(Y26 / $AE$2) * $AC$2 -> 0
D27: 0.6.5 InfoSec|Security Operation Monitoring and Verificiation | E27: 0.6.5.1 This includes: Network Connection Review (Firewall); Endpoint Security Verification and Testing; Scripting for MyJira Sync; Review Application Hosting and Cloud Infrastructure SCS; Vulnerability Scanning. | G27: Security | H27: 0.6.5.1 这包括：网络连接审查（防火墙）；终端安全验证和测试；MyJira Sync 的脚本编写；审查应用程序托管和云基础设施 SCS；漏洞扫描。 | T27: =$S27*DE_Cost!$B$1*8 -> 0 | U27: =$S27*DE_Cost!$B$1 -> 0 | X27: =IF(TRIM(P27)="", 0, LEN(P27) - LEN(SUBSTITUTE(P27, "&", "")) + 1) -> 0 | Y27: =S27 * X27 -> 0 | Z27: Y | AE27: =(Y27 / $AE$2) * $AC$2 -> 0
D28: 0.6.6 InfoSec|Identity and Access Management | E28: 0.6.6.1 Integration with central authentication and authorization platforms. | G28: Security | H28: 0.6.6.1 与中央身份验证和授权平台的集成。 | T28: =$S28*DE_Cost!$B$1*8 -> 0 | U28: =$S28*DE_Cost!$B$1 -> 0 | X28: =IF(TRIM(P28)="", 0, LEN(P28) - LEN(SUBSTITUTE(P28, "&", "")) + 1) -> 0 | Y28: =S28 * X28 -> 0 | Z28: Y | AE28: =(Y28 / $AE$2) * $AC$2 -> 0
D29: 0.6.7 InfoSec|Online Fraud Detection | E29: 0.6.7.1 Online fraud rules review and integration with AOFD platform | G29: Security | H29: 0.6.7.1 在线欺诈规则审查并与 AOFD 平台集成 | T29: =$S29*DE_Cost!$B$1*8 -> 0 | U29: =$S29*DE_Cost!$B$1 -> 0 | X29: =IF(TRIM(P29)="", 0, LEN(P29) - LEN(SUBSTITUTE(P29, "&", "")) + 1) -> 0 | Y29: =S29 * X29 -> 0 | Z29: Y | AE29: =(Y29 / $AE$2) * $AC$2 -> 0
D30: 0.6.8 InfoSec|Disaster Recovery and Business Continuity Management | E30: 0.6.8.1 Conduct a Business Impact Analysis (BIA) to identify critical IT services and determine the IT service continuity strategy. Develop and test comprehensive IT Service Continuity Plans to maintain business operations in the event of security incidents or system downtime | G30: Security | H30: 0.6.8.1 进行业务影响分析（BIA）以识别关键 IT 服务并确定 IT 服务连续性策略。制定并测试全面的 IT 服务连续性计划，以在发生安全事件或系统停机时维持业务运营。 | T30: =$S30*DE_Cost!$B$1*8 -> 0 | U30: =$S30*DE_Cost!$B$1 -> 0 | X30: =IF(TRIM(P30)="", 0, LEN(P30) - LEN(SUBSTITUTE(P30, "&", "")) + 1) -> 0 | Y30: =S30 * X30 -> 0 | Z30: Y | AE30: =(Y30 / $AE$2) * $AC$2 -> 0
C31: 0.7 EA|Enterprise Architecture | D31: 0.7.1 EA|Solution Architecture Review | E31: 0.7.1.1 Collaborative work for appropriate design of availability, resilience, integrations and ensure all EA standards are aligned and complied | G31: EA | H31: 0.7.1.1 协同工作，确保可用性、弹性、集成设计的合理性，并确保所有企业架构标准保持一致并得到遵守 | T31: =$S31*DE_Cost!$B$1*8 -> 0 | U31: =$S31*DE_Cost!$B$1 -> 0 | X31: =IF(TRIM(P31)="", 0, LEN(P31) - LEN(SUBSTITUTE(P31, "&", "")) + 1) -> 0 | Y31: =S31 * X31 -> 0 | Z31: Y | AE31: =(Y31 / $AE$2) * $AC$2 -> 0
C32: 0.8 F&IT|Data Technology | D32: 0.8.1 Data|Database deployment on-premises | E32: 0.8.1.1 Database deploy on-premises, database schema changes, data migration and database optimization | G32: FIT | H32: 0.8.1.1 本地数据库部署、数据库架构变更、数据迁移和数据库优化 | T32: =$S32*DE_Cost!$B$1*8 -> 0 | U32: =$S32*DE_Cost!$B$1 -> 0 | X32: =IF(TRIM(P32)="", 0, LEN(P32) - LEN(SUBSTITUTE(P32, "&", "")) + 1) -> 0 | Y32: =S32 * X32 -> 0 | Z32: Y | AE32: =(Y32 / $AE$2) * $AC$2 -> 0
D33: 0.8.2 Data|Database deployment in cloud | E33: 0.8.2.1 Database deploy in cloud database schema changes, data migration and database optimization | G33: FIT | H33: 0.8.2.1 数据库部署在云数据库模式变更、数据迁移和数据库优化 | T33: =$S33*DE_Cost!$B$1*8 -> 0 | U33: =$S33*DE_Cost!$B$1 -> 0 | X33: =IF(TRIM(P33)="", 0, LEN(P33) - LEN(SUBSTITUTE(P33, "&", "")) + 1) -> 0 | Y33: =S33 * X33 -> 0 | Z33: Y | AE33: =(Y33 / $AE$2) * $AC$2 -> 0
D34: 0.8.3 Data|Data migration & synchronization | E34: 0.8.3.1 During the transition between the old POS and the new POS, the old POS data needs to be migrated to the New POS. Historical data from the past six months will be migrated in one batch. Incremental data will be synchronized in near real-time (within 15 minutes). Currently, there are three proposed solutions (choose one): Directly connect to the old POS database in the cloud or migrate the old POS sales data tables as-is into the New POS database, with the New POS handling the old tables’ data for interface display. Based on option 1, transform the data into the New POS format and write it into the New POS sales tables. Directly use Javis APIs to query old POS sales data to support order data inquiries, refunds, and exchange/return operations. 0.8.3.1 新老POS切换期间，需要将老POS数据迁移至New POS里，历史近半年数据一次性迁移，增量数据近实时同步（15分钟内）。目前有三种方案（选其一）： 1. 云上直连老POS数据库或将老POS的销售数据表原样迁移至New POS的库中，由New POS处理老表数据用于界面展示 2. 在1的基础上，将数据转换成New POS的数据，写入到New POS的销售表里 3. 直接使用Javis的接口查询老POS销售数据，完成订单数据查询、退款、退换货操作 | G34: Data & Jarvis | H34: 0.8.3.1 在旧 POS 系统和新 POS 系统过渡期间，旧 POS 数据需要迁移到新 POS 系统。 过去六个月的历史数据将一次性迁移。 增量数据将进行近实时同步（15 分钟内）。 目前，提出了三种解决方案（选择其一）： 直接连接到云端的旧 POS 数据库，或将旧 POS 销售数据表原样迁移到新 POS 数据库中，由新 POS 处理这些旧表的数据以进行界面显示。 根据选项 1，将数据转换为新的 POS 格式并写入新的 POS 销售表中。 直接使用 Javis API 查询旧的 POS 销售数据，以支持订单数据查询、退款以及换货/退货操作。 | K34: Jarvis | T34: =$S34*DE_Cost!$B$1*8 -> 0 | U34: =$S34*DE_Cost!$B$1 -> 0 | X34: =IF(TRIM(P34)="", 0, LEN(P34) - LEN(SUBSTITUTE(P34, "&", "")) + 1) -> 0 | Y34: =S34 * X34 -> 0 | Z34: Y | AE34: =(Y34 / $AE$2) * $AC$2 -> 0
A35: 1(Minimum scope) | B35: 2. Foundation operational functions 基础运营功能 | C35: 2.1 Merch & FnB product ordering 商品&餐饮点单 | D35: 2.1.1 [Merch] Add/delete product|Add product to shopping list 添加商品 | E35: 2.1.1.1 As Merch cashier, I need New POS will be able to add product to shopping list by barcode scanning or tap button, as to process shopping in store ordering. | F35: Items in one transaction may more than one thousand lines. | H35: 2.1.1.1 作为收银员，我需要新 POS 系统能够通过条形码扫描或点击按钮将商品添加到购物清单，以便处理店内购物订单。 | I35: 一个交易中的商品可能超过一千行。 | N35: 购物清单-添加+清单联动 | O35: 不包含优惠券等促销计算逻辑（需其他EPIC计算工时间） | P35: Android Developer & Front-end Developer & Product Designer & Quality Assurance & Product Manager & Delivery Manager | S35: 5 | T35: =$S35*DE_Cost!$B$1*8 -> 48 | U35: =$S35*DE_Cost!$B$1 -> 6 | V35: 0 | W35: 0 | X35: =IF(TRIM(P35)="", 0, LEN(P35) - LEN(SUBSTITUTE(P35, "&", "")) + 1) -> 6 | Y35: =S35 * X35 -> 30 | Z35: N | AA35: 建议5人天，估的工时过少可能，点击按钮添加购物清单如何实现，这里需要找到商品这一步 | AE35: =(Y35 / $AE$2) * $AC$2 -> 10968.133
A36: 1(Minimum scope) | B36: 2. Foundation operational functions 基础运营功能 | C36: 2.1 Merch & FnB product ordering 商品&餐饮点单 | D36: 2.1.1 [Merch] Add/delete product|Delete product in shopping list 删除商品 | E36: 2.1.1.2 As Merch cashier, I need New POS will be able to delete product in shopping list by slide w/ tap button, as to process shopping in store ordering. | H36: 2.1.1.2 作为收银员，我需要新 POS 系统能够通过滑动并点击按钮来删除购物清单中的商品，以便处理店内订单购物。 | N36: 购物清单-删除 | O36: (删除（0.5天） | P36: Android Developer & Front-end Developer & Product Designer & Quality Assurance & Product Manager & Delivery Manager | S36: 2 | T36: =$S36*DE_Cost!$B$1*8 -> 19.2 | U36: =$S36*DE_Cost!$B$1 -> 2.4 | V36: 0 | W36: 0 | X36: =IF(TRIM(P36)="", 0, LEN(P36) - LEN(SUBSTITUTE(P36, "&", "")) + 1) -> 6 | Y36: =S36 * X36 -> 12 | Z36: Y | AE36: =(Y36 / $AE$2) * $AC$2 -> 4387.2532
